Workbook

Sheet README
B1: Type 31 Frigate – Whole-Life Cost, Sensitivity and Risk Model
B2: Prepared by Sino Lam · Illustrative model built entirely from publicly available data · All costs in £m, approximate 2023-24 prices unless stated
B4: Purpose
B5: Estimate the whole-life cost (WLC) of the Royal Navy's five Type 31 (Inspiration-class) general-purpose frigates, test which assumptions drive that cost, and quantify the uncertainty around it.
B7: Questions answered
B8: 1. How much will the class cost over its life? (Summary, WLC_Model)
B9: 2. Is the estimate consistent with comparable programmes? (Benchmarks – US, Canadian, Australian and Danish data)
B10: 3. Which assumptions matter most? (Sensitivity – one-way tornado analysis; Assumptions_Log)
B11: 4. How confident can we be in the estimate? (Risk_Results – 2,000-iteration Monte Carlo simulation)
B13: Workbook structure
B14: Inputs – every input in one place, with low / base / high values, type (Sourced, Derived, Benchmark, Assumption) and source.
B15: Assumptions_Log – the reasoning, evidence, confidence rating and cost impact of every analyst assumption.
... B38: • Several values are analyst assumptions; each is explained and rated on the Assumptions_Log sheet.

Sheet Summary
A1: Type 31 Frigate – Whole-Life Cost Summary
A2: £m, approx. 2023-24 prices · Five ships · Calibrated to international benchmarks (see Benchmarks)
A4: Headline results | B4: £m
A5: Whole-life cost (deterministic, undiscounted) | B5: =WLC_Model!C22 -> 6039.9817
A6: Whole-life cost per ship | B6: =B5/Inputs!$E$5 -> 1207.9963
A7: Acquisition cost | B7: =WLC_Model!C16 -> 2310
A8: Support cost (operate, maintain, support, update, dispose) | B8: =SUM(WLC_Model!C17:C21) -> 3729.9817
A9: Support share of whole-life cost | B9: =B8/B5 -> 0.61754851
A10: Direct-cost-only WLC (before benchmark calibration) | B10: =B5-WLC_Model!C19 -> 4765.5443
A11: Present value of future costs (from base year, 3.5%) | B11: =WLC_Model!C26 -> 3117.9205
A12: Risk: P50 whole-life cost (Monte Carlo) | B12: =Risk_Results!C8 -> 6297.3155
A13: Risk: P80 whole-life cost (Monte Carlo) | B13: =Risk_Results!C9 -> 6737.487
A14: Risk: contingency P80 minus deterministic | B14: =B13-B5 -> 697.5053
A15: Risk: probability WLC exceeds deterministic estimate | B15: =Risk_Results!C14 -> 0.724
A17: Cost breakdown | B17: £m | C17: Share
A18: Acquisition | B18: =WLC_Model!C16 -> 2310 | C18: =B18/$B$24 -> 0.38245149
A19: Operating (crew, fuel, port) | B19: =WLC_Model!C17 -> 1342.514 | C19: =B19/$B$24 -> 0.2222712
A20: Maintenance / upkeep | B20: =WLC_Model!C18 -> 713.0303 | C20: =B20/$B$24 -> 0.11805173
A21: Indirect & sustaining support | B21: =WLC_Model!C19 -> 1274.4375 | C21: =B21/$B$24 -> 0.21100022
A22: Mid-life updates | B22: =WLC_Model!C20 -> 375 | C22: =B22/$B$24 -> 0.06208628
A23: Disposal | B23: =WLC_Model!C21 -> 25 | C23: =B23/$B$24 -> 0.0041390854
A24: Total | B24: =SUM(B18:B23) -> 6039.9817 | C24: =SUM(C18:C23) -> 1
A27: Key findings
A28: ="1. The five-ship class is estimated to cost about £"&TEXT(B5/1000,"0.0")&"bn over its life; the £"&TEXT(B7/1000,"0.0")&"bn purchase price is only "&TEXT(B7/B5,"0%")&" of that." -> 1. The five-ship class is estimated to cost about £6.0bn over its life; the £2.3bn purchase price is only 38% of that.
A29: ="2. Support is "&TEXT(B9,"0%")&" of whole-life cost, in line with US (c.59-70%) and Canadian (72%) frigate evidence. Using UK direct costs alone would understate WLC by about £"&TEXT((B5-B10)/1000,"0.0")&"bn." -> 2. Support is 62% of whole-life cost, in line with US (c.59-70%) and Canadian (72%) frigate evidence. Using UK direct costs alone would understate WLC by about £1.3bn.
A30: ="3. Allowing for uncertainty, there is an 80% chance the WLC is below £"&TEXT(B13/1000,"0.0")&"bn – a contingency of about £"&TEXT(B14,"#,##0")&"m above the point estimate." -> 3. Allowing for uncertainty, there is an 80% chance the WLC is below £6.7bn – a contingency of about £698m above the point estimate.

Sheet Assumptions_Log
A1: Assumptions log
A2: Every analyst assumption, why it was chosen, the evidence behind it, how confident we are, and how much it moves the answer. Values link live to Inputs; impact links to Sensitivity.
A4: ID | B4: Assumption | C4: Base | D4: Low | E4: High | F4: Why this value | G4: Evidence | H4: Confidence | I4: WLC swing low→high (£m)
A5: L | B5: Each ship stays in service for 25 years, with 20 and 30 years as the range. | C5: =IF(Inputs!$E$8="","",Inputs!$E$8) -> 25 | D5: =IF(Inputs!$D$8="","",Inputs!$D$8) -> 20 | E5: =IF(Inputs!$F$8="","",Inputs!$F$8) -> 30 | F5: 25 years is the standard planning life for modern frigates and the life used in the US FFG-62 estimate. Type 23s show lives can stretch well beyond plan when replacements slip. | G5: FFG-62 SAR (25-year life per ship); Type 23 planned for 18 years, some served 30+ (Naval Technology, 2025). | H5: Medium | I5: =IFERROR(INDEX(Sensitivity!$H$5:$H$13,MATCH(Inputs!$B$8,Sensitivity!$A$5:$A$13,0)),"–") -> 1331.9927
A6: G | B6: Acquisition costs grow 5% above the £2.2bn budget (range 0-20%). | C6: =IF(Inputs!$E$10="","",Inputs!$E$10) -> 0.05 | D6: =IF(Inputs!$D$10="","",Inputs!$D$10) -> 0 | E6: =IF(Inputs!$F$10="","",Inputs!$F$10) -> 0.2 | F6: MoD's approved figure excludes inflation since 2022, and the prime contractor has reported cost pressures. A modest base with a fat upside reflects a fixed-price contract that shifts some, but not all, risk to industry. | G6: MoD letter to PAC (May 2023); Babcock £90m loss and dispute over cost increases (Naval Technology 2024; Janes 2023). | H6: Medium | I6: =IFERROR(INDEX(Sensitivity!$H$5:$H$13,MATCH(Inputs!$B$10,Sensitivity!$A$5:$A$13,0)),"–") -> 440
A7: PS | B7: Crew pay is 70% of direct operating cost (range 60-80%). | C7: =IF(Inputs!$E$15="","",Inputs!$E$15) -> 0.7 | D7: =IF(Inputs!$D$15="","",Inputs!$D$15) -> 0.6 | E7: =IF(Inputs!$F$15="","",Inputs!$F$15) -> 0.8 | F7: Used to scale Type 23 running costs to Type 31's smaller crew. US FFG-62 data puts manpower at 75% of manpower-plus-operations. | G7: FFG-62 SAR Dec 2022 (unit-level manpower $16.6m vs unit operations $5.4m per ship-year). | H7: Medium | I7: =IFERROR(INDEX(Sensitivity!$H$5:$H$13,MATCH(Inputs!$B$15,Sensitivity!$A$5:$A$13,0)),"–") -> 269.75165
A8: OPU | B8: Running costs estimated by analogy may be 10% lower to 25% higher than calculated. | C8: =IF(Inputs!$E$18="","",Inputs!$E$18) -> 1 | D8: =IF(Inputs!$D$18="","",Inputs!$D$18) -> 0.9 | E8: =IF(Inputs!$F$18="","",Inputs!$F$18) -> 1.25 | F8: Estimating a new class from an older one is uncertain; history shows support costs are usually underestimated, so the range is skewed upward. | G8: GAO-20-2: Navy underestimated sustainment costs by $130bn across six ship classes. | H8: Low | I8: =IFERROR(INDEX(Sensitivity!$H$5:$H$13,MATCH(Inputs!$B$18,Sensitivity!$A$5:$A$13,0)),"–") -> 761.20542
A9: UKY / UKF | B9: Type 23 upkeep spend covers 11 years and an average fleet of 12 ships. | F9: Turns a published total into a cost per ship-year. Fleet size fell from 13 to 8 over the period, so 12 is a rough average weighted to the earlier years. | G9: Written PQ, 17 Mar 2025 (£941.2m since 2014); Type 23 fleet numbers (Naval Technology, 2025). | H9: Low | I9: –
A10: MF | B10: Type 31 needs 80% of the Type 23's upkeep (range 60-120%). | C10: =IF(Inputs!$E$24="","",Inputs!$E$24) -> 0.8 | D10: =IF(Inputs!$D$24="","",Inputs!$D$24) -> 0.6 | E10: =IF(Inputs!$F$24="","",Inputs!$F$24) -> 1.2 | F10: A new ship on a proven commercial-standard hull should be cheaper to maintain than 30-year-old Type 23s, but costs rise as ships age. | G10: Type 31 based on the Danish Iver Huitfeldt / Arrowhead 140 design; Type 23 upkeep evidence. | H10: Low | I10: =IFERROR(INDEX(Sensitivity!$H$5:$H$13,MATCH(Inputs!$B$24,Sensitivity!$A$5:$A$13,0)),"–") -> 866.33182
A11: IND | B11: Indirect and sustaining support adds 62% on top of direct running costs (range 30-82%). | C11: =IF(Inputs!$E$26="","",Inputs!$E$26) -> 0.62 | D11: =IF(Inputs!$D$26="","",Inputs!$D$26) -> 0.3 | E11: =IF(Inputs!$F$26="","",Inputs!$F$26) -> 0.82 | F11: UK published figures cover only direct costs. The US FFG-62 estimate breaks down full support costs, giving the ratio of indirect to direct support. Without this, support would be far below international norms. | G11: FFG-62 SAR Dec 2022; cross-checked against GAO (c.70%) and Canadian PBO (72%) support shares. | H11: Medium | I11: =IFERROR(INDEX(Sensitivity!$H$5:$H$13,MATCH(Inputs!$B$26,Sensitivity!$A$5:$A$13,0)),"–") -> 1068.883
A12: MLU | B12: Each ship has a £75m mid-life update in its 13th year (range £50-150m). | C12: =IF(Inputs!$E$27="","",Inputs!$E$27) -> 75 | D12: =IF(Inputs!$D$27="","",Inputs!$D$27) -> 50 | E12: =IF(Inputs!$F$27="","",Inputs!$F$27) -> 150 | F12: Frigates typically receive a major refit and capability update halfway through life. Type 23 refits have cost over £100m, but Type 31 is simpler and designed for upgrades. | G12: HMS Iron Duke refit >£100m (Naval Technology, 2025); FFG-62 continuous system improvements c.11% of annual O&S. | H12: Low | I12: =IFERROR(INDEX(Sensitivity!$H$5:$H$13,MATCH(Inputs!$B$27,Sensitivity!$A$5:$A$13,0)),"–") -> 500
A13: D | B13: Disposal costs £5m per ship (range £2-15m). | C13: =IF(Inputs!$E$29="","",Inputs!$E$29) -> 5 | D13: =IF(Inputs!$D$29="","",Inputs!$D$29) -> 2 | E13: =IF(Inputs!$F$29="","",Inputs!$F$29) -> 15 | F13: Disposal is a small share of whole-life cost in every comparator, so precision matters little. | G13: FFG-62 SAR (c.$9m per ship); Canadian PBO (0.6% of life-cycle cost). | H13: Medium | I13: =IFERROR(INDEX(Sensitivity!$H$5:$H$13,MATCH(Inputs!$B$29,Sensitivity!$A$5:$A$13,0)),"–") -> 65
A14: ISD1 / INT | B14: First ship in service 2027, then one per year. | F14: Matches published in-service plans for HMS Venturer and the class. Timing affects present value but not undiscounted WLC. | G14: Naval Technology (2024): five ships into service from 2027; Royal Navy (2025). | H14: Medium | I14: –
A15: Profile | B15: Acquisition spend profile 2019-2031 (WLC_Model row 5). | F15: Spreads the £2.2bn from contract award to final delivery, peaking during main build. Affects timing and present value only. | G15: Contract award Nov 2019; Babcock had recognised over £600m revenue by April 2023. | H15: Low | I15: –
A16: Price base | B16: The £2.2bn budget is treated as approximately 2023-24 prices. | F16: The MoD figure mixes years and includes 2019 inflation forecasts. No published breakdown allows exact rebasing, so the acquisition growth range absorbs this. | G16: MoD letter to PAC (May 2023). | H16: Low | I16: –
A17: BY / R | B17: Present values use 2026 as base year and a 3.5% real discount rate. | F17: Green Book standard for public sector appraisal; costs before 2026 are sunk and excluded from present value. | G17: HM Treasury Green Book. | H17: High | I17: –

Sheet Benchmarks
A1: International benchmarks
A2: Comparators are expressed as ratios (shares, multiples) so no currency conversion is needed. Blue = published figure, black = calculation.
A4: A. Support (operating & support) share of whole-life cost
A5: Programme | B5: Acquisition | C5: Operating & support | D5: Other (dev't, disposal) | E5: Total | F5: Support share | G5: Source and notes
A6: US Navy ships – GAO rule of thumb | F6: 0.7 | G6: GAO-20-2 (2019): about 70% of a ship's life-cycle cost is operations and maintenance.
A7: Canada – Canadian Surface Combatant (15 ships), C$bn | B7: 80.2 | C7: 219.8 | D7: =4.3+1.7 -> 6 | E7: =SUM(B7:D7) -> 306 | F7: =C7/E7 -> 0.71830065 | G7: Parliamentary Budget Officer, Life Cycle Cost of the Canadian Surface Combatants, Oct 2022. Development C$4.3bn, disposal C$1.7bn.
A8: US Navy – FFG-62 Constellation frigate (20 ships), US$m CY2020 | B8: 20342.5 | C8: =B21*20*25 -> 29000 | E8: =SUM(B8:D8) -> 49342.5 | F8: =C8/E8 -> 0.58772863 | G8: Selected Acquisition Report, Dec 2022. O&S = $57.9m per ship-year × 20 ships × 25 years (disposal included in O&S).
A9: Type 31 – this model, direct costs only | B9: =WLC_Model!C16 -> 2310 | C9: =SUM(WLC_Model!C17:C18)+SUM(WLC_Model!C20:C21) -> 2455.5443 | E9: =SUM(B9:D9) -> 4765.5443 | F9: =C9/E9 -> 0.51527048 | G9: UK direct costs: crew, fuel, port visits, upkeep periods, mid-life update and disposal.
A10: Type 31 – this model, calibrated (used for results) | B10: =WLC_Model!C16 -> 2310 | C10: =SUM(WLC_Model!C17:C21) -> 3729.9817 | E10: =SUM(B10:D10) -> 6039.9817 | F10: =C10/E10 -> 0.61754851 | G10: Adds indirect and sustaining support calibrated to FFG-62 (section B).
A13: B. US Navy FFG-62 annual operating & support cost per ship, by element (US$m, CY2020)
A14: Cost element | B14: US$m per ship-year | C14: Share | D14: Equivalent in UK model
A15: Unit-level manpower | B15: 16.6 | C15: =B15/$B$21 -> 0.2862069 | D15: Direct: operating cost (crew)
A16: Unit operations (fuel, consumables) | B16: 5.4 | C16: =B16/$B$21 -> 0.093103448 | D16: Direct: operating cost (non-crew)
A17: Maintenance | B17: 9.8 | C17: =B17/$B$21 -> 0.16896552 | D17: Direct: maintenance / upkeep
A18: Sustaining support | B18: 10.7 | C18: =B18/$B$21 -> 0.18448276 | D18: Indirect & sustaining support
A19: Continued system improvements | B19: 6.5 | C19: =B19/$B$21 -> 0.11206897 | D19: Mid-life update (partly)
A20: Other (indirect support) | B20: 9 | C20: =B20/$B$21 -> 0.15517241 | D20: Indirect & sustaining support
A21: Total O&S per ship-year | B21: =SUM(B15:B20) -> 58
A22: Calibrated uplift: (sustaining support + other) ÷ (manpower + operations + maintenance) | C22: =ROUND((B18+B20)/(B15+B16+B17),2) -> 0.62 | D22: → feeds Inputs: Indirect & sustaining support uplift (base case)
A23: FFG-62 manpower share of direct operating cost (manpower ÷ (manpower + operations)) | C23: =B15/(B15+B16) -> 0.75454545 | D23: → supports Inputs: personnel share of direct operating cost (70%)
A24: FFG-62 annual O&S as % of unit acquisition cost | C24: =B21/(B8/20) -> 0.057023473
A25: Type 31 (calibrated) annual running cost as % of unit acquisition cost | C25: =(Inputs!$E$19+Inputs!$E$25)*(1+Inputs!$E$26)/(WLC_Model!C16/Inputs!$E$5) -> 0.057662021 | D25: Very close to FFG-62 – an independent cross-check that calibrated running costs are proportionate to the ship's value
A26: Source: FFG(62) Selected Acquisition Report, December 2022 (Component Independent Cost Estimate, April 2020).
A28: C. Other comparators (context only, not used in calculations)
A29: Comparator | B29: Value | C29: Unit | D29: Per ship | F29: Confidence | G29: Source and notes
A30: Australia – ANZAC class frigate sustainment, 2018-19 budget (8 ships) | B30: 374 | C30: A$m/yr | D30: =B30/8 -> 46.75 | F30: Medium | G30: ANAO, Anzac Class Frigates – Sustainment (2019). Materiel sustainment only; shows support of an in-service frigate class running at tens of millions per ship per year.
A31: Denmark – Iver Huitfeldt class (parent design of Type 31), build cost | B31: 325 | C31: US$m/ship | F31: Low | G31: Wikipedia infobox (uncited). Supports Type 31's low build cost (c.£250m production cost per ship) from reusing a proven hull.
A32: Denmark – Iver Huitfeldt class crew | B32: 165 | C32: people | F32: Low | G32: Wikipedia infobox (uncited). Type 31 is planned to run with a much smaller crew (105-115).
A33: UK – Type 23 crew (HMS St Albans) | B33: 185 | C33: people | F33: High | G33: Royal Navy ship page: crew of 185, accommodation for up to 205.
A34: UK – Type 31 average production cost per ship | B34: 250 | C34: £m/ship | F34: High | G34: Babcock contract, Nov 2019 (Naval Technology, 2024). Excludes MoD-side costs within the £2.2bn.
A37: What the benchmarks changed
A38: ="Using UK direct costs alone, support would be "&TEXT(F9,"0%")&" of whole-life cost – well below the 59-72% seen in US and Canadian frigate programmes. Adding indirect and sustaining support calibrated to FFG-62 raises it to "&TEXT(F10,"0%")&", within the benchmark range." -> Using UK direct costs alone, support would be 52% of whole-life cost – well below the 59-72% seen in US and Canadian frigate programmes. Adding indirect and sustaining support calibrated to FFG-62 raises it to 62%, within the benchmark range.

Sheet Inputs
A1: Inputs and assumptions
A2: All costs £m, approx. 2023-24 prices. Low and High feed the Sensitivity sheet; Low / Base / High are the min / most likely / max for the Monte Carlo. Reasoning for each assumption is on Assumptions_Log.
A4: ID | B4: Parameter | C4: Unit | D4: Low | E4: Base | F4: High | G4: Type | H4: Source / notes
A5: N | B5: Number of ships | C5: ships | E5: 5 | G5: Sourced | H5: Five Inspiration-class ships on contract with Babcock (MoD letter to PAC, 25 May 2023).
A6: ISD1 | B6: First ship in service (financial year) | C6: year | E6: 2027 | G6: Assumption | H6: HMS Venturer planned to enter service c.2027; five ships in service from 2027 with final handover around 2028-2030 (Naval Technology, 2024). See Assumptions_Log.
A7: INT | B7: Interval between ship in-service dates | C7: years | E7: 1 | G7: Assumption | H7: Simplifying assumption: one ship per year.
A8: L | B8: Service life per ship | C8: years | D8: 20 | E8: 25 | F8: 30 | G8: Assumption | H8: 25 years matches the planning life in the US Navy FFG-62 estimate and early Type 26 planning. Type 23s were planned for 18 years but extended past 30.
A9: ACQ | B9: Approved acquisition budget (5 ships) | C9: £m | E9: 2200 | G9: Sourced | H9: Uplifted from £2.0bn to £2.2bn in 2022. Covers Babcock contract, c.£100m GFX, trials, spares, integration facility (MoD letter to PAC, 25 May 2023).
A10: G | B10: Acquisition cost growth above approved budget | C10: % | D10: 0 | E10: 0.05 | F10: 0.2 | G10: Assumption | H10: MoD states recent inflation is not reflected in the £2.2bn; Babcock booked a £90m loss citing design changes and labour costs (Naval Technology, July 2024).
A11: OP23 | B11: Type 23 average direct operating cost per ship (FY13-14) | C11: £m/yr | E11: 11.735 | G11: Sourced | H11: MoD FOI 2015/06440, Annex A. Includes personnel, fuel, port visits, travel. Excludes maintenance, base support, overheads, aircraft, training.
A12: DEF14 | B12: GDP deflator 2013-14 (2023-24 = 100) | C12: index | E12: 76.189 | G12: Sourced | H12: HM Treasury GDP deflators at market prices, June 2024 release.
A13: DEF24 | B13: GDP deflator 2023-24 | C13: index | E13: 100 | G13: Sourced | H13: HM Treasury GDP deflators, June 2024 release (base year).
A14: UPL | B14: Price uplift 2013-14 to 2023-24 | C14: factor | E14: =E13/E12 -> 1.3125254 | G14: Derived | H14: Deflator 2023-24 ÷ deflator 2013-14.
A15: PS | B15: Personnel share of direct operating cost | C15: % | D15: 0.6 | E15: 0.7 | F15: 0.8 | G15: Benchmark | H15: US Navy FFG-62: unit-level manpower is 75% of manpower + unit operations ($16.6m of $22.0m per ship-year, SAR Dec 2022). 70% used, as UK fuel and port costs are proportionally higher.
A16: C23 | B16: Type 23 crew complement | C16: people | E16: 185 | G16: Sourced | H16: Royal Navy, HMS St Albans ship page: 'sailed by a crew of 185, but with accommodation for up to 205'. Crew varies between ships and over time; 185 used for the class.
A17: C31 | B17: Type 31 crew complement | C17: people | D17: 100 | E17: 105 | F17: 115 | G17: Sourced | H17: Crew of up to 105 (GOV.UK, 2021); Royal Navy now cites around 115 for HMS Venturer.
A18: OPU | B18: Operating cost estimating uncertainty factor | C18: factor | D18: 0.9 | E18: 1 | F18: 1.25 | G18: Assumption | H18: Captures the uncertainty of estimating by analogy with an older class. Skewed upward because new-ship running costs are usually underestimated (GAO-20-2).
A19: OP31 | B19: Type 31 direct operating cost per ship-year | C19: £m/yr | E19: =E11*E14*(E15*E17/E16+(1-E15))*E18 -> 10.740112 | G19: Derived | H19: T23 cost × price uplift × (personnel share × crew ratio + non-personnel share) × uncertainty factor.
A20: UK23 | B20: Type 23 upkeep spend on completed upkeeps since 2014 | C20: £m | E20: 941.2 | G20: Sourced | H20: Written parliamentary answer, 17 March 2025 (reported by Naval Technology). Cash prices.
A21: UKY | B21: Years covered by upkeep spend | C21: years | E21: 11 | G21: Assumption | H21: 2014 to 2024 inclusive.
A22: UKF | B22: Average Type 23 fleet size over the period | C22: ships | E22: 12 | G22: Assumption | H22: Fleet fell from 13 to 8 over the period; 12 used as a rough average.
A23: M23 | B23: Type 23 upkeep cost per ship-year | C23: £m/yr | E23: =E20/(E21*E22) -> 7.130303 | G23: Derived | H23: Upkeep spend ÷ (years × fleet size).
A24: MF | B24: Type 31 maintenance scaling factor vs Type 23 | C24: factor | D24: 0.6 | E24: 0.8 | F24: 1.2 | G24: Assumption | H24: A newer ship based on a proven Danish design should need less maintenance than an ageing Type 23; the high case allows for ageing later in life.
A25: M31 | B25: Type 31 maintenance cost per ship-year | C25: £m/yr | E25: =E23*E24 -> 5.7042424 | G25: Derived | H25: Type 23 upkeep per ship-year × scaling factor.
A26: IND | B26: Indirect & sustaining support uplift on direct running costs | C26: factor | D26: 0.3 | E26: =Benchmarks!$C$22 -> 0.62 | F26: 0.82 | G26: Benchmark | H26: Base calibrated to US Navy FFG-62 (SAR Dec 2022): (sustaining support + other) ÷ (manpower + unit operations + maintenance) = 0.62. High (0.82) adds continuous system improvements; low (0.30) assumes leaner UK overheads. Covers base support, training, spares and in-service support missing from the UK direct-cost figures.
A27: MLU | B27: Mid-life update cost per ship | C27: £m | D27: 50 | E27: 75 | F27: 150 | G27: Assumption | H27: Scaled from Type 23 experience: HMS Iron Duke's 2023 refit cost over £100m (Naval Technology, 2025).
A28: MLUY | B28: Mid-life update in year of service | C28: year no. | E28: 13 | G28: Assumption | H28: Roughly halfway through a 25-year life.
A29: D | B29: Disposal cost per ship | C29: £m | D29: 2 | E29: 5 | F29: 15 | G29: Benchmark | H29: US FFG-62 disposal is c.$9m per ship (SAR Dec 2022, $179.6m for 20 ships); Canadian CSC disposal is 0.6% of life-cycle cost (PBO 2022). £5m base.
A30: R | B30: Real discount rate | C30: % | E30: 0.035 | G30: Sourced | H30: HM Treasury Green Book social time preference rate (years 0-30).
A31: BY | B31: Present value base year | C31: year | E31: 2026 | G31: Assumption | H31: Current year; spend before this is treated as sunk.

Sheet Sensitivity
A1: One-way sensitivity analysis (tornado)
A2: Each input is moved to its Low and High value from the Inputs sheet while all others stay at Base. Output: undiscounted whole-life cost (£m).
A3: Base whole-life cost (£m): | D3: =WLC_Model!C22 -> 6039.9817
A4: Input varied | B4: Low value | C4: High value | D4: WLC at low (£m) | E4: WLC at high (£m) | F4: Change at low (£m) | G4: Change at high (£m) | H4: Swing (£m) | I4: Swing as % of base
A5: =Inputs!B29 -> Disposal cost per ship | B5: =Inputs!$D$29 -> 2 | C5: =Inputs!$F$29 -> 15 | D5: =Inputs!$E$9*(1+Inputs!$E$10)+Inputs!$E$5*Inputs!$E$8*(Inputs!$E$11*Inputs!$E$14*(Inputs!$E$15*Inputs!$E$17/Inputs!$E$16+(1-Inputs!$E$15))*Inputs!$E$18+Inputs!$E$23*Inputs!$E$24)*(1+Inputs!$E$26)+Inputs!$E$5*(Inputs!$E$27+$B5) -> 6024.9817 | E5: =Inputs!$E$9*(1+Inputs!$E$10)+Inputs!$E$5*Inputs!$E$8*(Inputs!$E$11*Inputs!$E$14*(Inputs!$E$15*Inputs!$E$17/Inputs!$E$16+(1-Inputs!$E$15))*Inputs!$E$18+Inputs!$E$23*Inputs!$E$24)*(1+Inputs!$E$26)+Inputs!$E$5*(Inputs!$E$27+$C5) -> 6089.9817 | F5: =D5-$D$3 -> -15 | G5: =E5-$D$3 -> 50 | H5: =ABS(E5-D5) -> 65 | I5: =H5/$D$3 -> 0.010761622
A6: =Inputs!B17 -> Type 31 crew complement | B6: =Inputs!$D$17 -> 100 | C6: =Inputs!$F$17 -> 115 | D6: =Inputs!$E$9*(1+Inputs!$E$10)+Inputs!$E$5*Inputs!$E$8*(Inputs!$E$11*Inputs!$E$14*(Inputs!$E$15*$B6/Inputs!$E$16+(1-Inputs!$E$15))*Inputs!$E$18+Inputs!$E$23*Inputs!$E$24)*(1+Inputs!$E$26)+Inputs!$E$5*(Inputs!$E$27+Inputs!$E$29) -> 5980.9736 | E6: =Inputs!$E$9*(1+Inputs!$E$10)+Inputs!$E$5*Inputs!$E$8*(Inputs!$E$11*Inputs!$E$14*(Inputs!$E$15*$C6/Inputs!$E$16+(1-Inputs!$E$15))*Inputs!$E$18+Inputs!$E$23*Inputs!$E$24)*(1+Inputs!$E$26)+Inputs!$E$5*(Inputs!$E$27+Inputs!$E$29) -> 6157.9981 | F6: =D6-$D$3 -> -59.008172 | G6: =E6-$D$3 -> 118.01634 | H6: =ABS(E6-D6) -> 177.02452 | I6: =H6/$D$3 -> 0.029308784
A7: =Inputs!B15 -> Personnel share of direct operating cost | B7: =Inputs!$D$15 -> 0.6 | C7: =Inputs!$F$15 -> 0.8 | D7: =Inputs!$E$9*(1+Inputs!$E$10)+Inputs!$E$5*Inputs!$E$8*(Inputs!$E$11*Inputs!$E$14*($B7*Inputs!$E$17/Inputs!$E$16+(1-$B7))*Inputs!$E$18+Inputs!$E$23*Inputs!$E$24)*(1+Inputs!$E$26)+Inputs!$E$5*(Inputs!$E$27+Inputs!$E$29) -> 6174.8576 | E7: =Inputs!$E$9*(1+Inputs!$E$10)+Inputs!$E$5*Inputs!$E$8*(Inputs!$E$11*Inputs!$E$14*($C7*Inputs!$E$17/Inputs!$E$16+(1-$C7))*Inputs!$E$18+Inputs!$E$23*Inputs!$E$24)*(1+Inputs!$E$26)+Inputs!$E$5*(Inputs!$E$27+Inputs!$E$29) -> 5905.1059 | F7: =D7-$D$3 -> 134.87582 | G7: =E7-$D$3 -> -134.87582 | H7: =ABS(E7-D7) -> 269.75165 | I7: =H7/$D$3 -> 0.044661004
A8: =Inputs!B10 -> Acquisition cost growth above approved budget | B8: =Inputs!$D$10 -> 0 | C8: =Inputs!$F$10 -> 0.2 | D8: =Inputs!$E$9*(1+$B8)+Inputs!$E$5*Inputs!$E$8*(Inputs!$E$11*Inputs!$E$14*(Inputs!$E$15*Inputs!$E$17/Inputs!$E$16+(1-Inputs!$E$15))*Inputs!$E$18+Inputs!$E$23*Inputs!$E$24)*(1+Inputs!$E$26)+Inputs!$E$5*(Inputs!$E$27+Inputs!$E$29) -> 5929.9817 | E8: =Inputs!$E$9*(1+$C8)+Inputs!$E$5*Inputs!$E$8*(Inputs!$E$11*Inputs!$E$14*(Inputs!$E$15*Inputs!$E$17/Inputs!$E$16+(1-Inputs!$E$15))*Inputs!$E$18+Inputs!$E$23*Inputs!$E$24)*(1+Inputs!$E$26)+Inputs!$E$5*(Inputs!$E$27+Inputs!$E$29) -> 6369.9817 | F8: =D8-$D$3 -> -110 | G8: =E8-$D$3 -> 330 | H8: =ABS(E8-D8) -> 440 | I8: =H8/$D$3 -> 0.072847902
A9: =Inputs!B27 -> Mid-life update cost per ship | B9: =Inputs!$D$27 -> 50 | C9: =Inputs!$F$27 -> 150 | D9: =Inputs!$E$9*(1+Inputs!$E$10)+Inputs!$E$5*Inputs!$E$8*(Inputs!$E$11*Inputs!$E$14*(Inputs!$E$15*Inputs!$E$17/Inputs!$E$16+(1-Inputs!$E$15))*Inputs!$E$18+Inputs!$E$23*Inputs!$E$24)*(1+Inputs!$E$26)+Inputs!$E$5*($B9+Inputs!$E$29) -> 5914.9817 | E9: =Inputs!$E$9*(1+Inputs!$E$10)+Inputs!$E$5*Inputs!$E$8*(Inputs!$E$11*Inputs!$E$14*(Inputs!$E$15*Inputs!$E$17/Inputs!$E$16+(1-Inputs!$E$15))*Inputs!$E$18+Inputs!$E$23*Inputs!$E$24)*(1+Inputs!$E$26)+Inputs!$E$5*($C9+Inputs!$E$29) -> 6414.9817 | F9: =D9-$D$3 -> -125 | G9: =E9-$D$3 -> 375 | H9: =ABS(E9-D9) -> 500 | I9: =H9/$D$3 -> 0.082781707
A10: =Inputs!B18 -> Operating cost estimating uncertainty factor | B10: =Inputs!$D$18 -> 0.9 | C10: =Inputs!$F$18 -> 1.25 | D10: =Inputs!$E$9*(1+Inputs!$E$10)+Inputs!$E$5*Inputs!$E$8*(Inputs!$E$11*Inputs!$E$14*(Inputs!$E$15*Inputs!$E$17/Inputs!$E$16+(1-Inputs!$E$15))*$B10+Inputs!$E$23*Inputs!$E$24)*(1+Inputs!$E$26)+Inputs!$E$5*(Inputs!$E$27+Inputs!$E$29) -> 5822.4945 | E10: =Inputs!$E$9*(1+Inputs!$E$10)+Inputs!$E$5*Inputs!$E$8*(Inputs!$E$11*Inputs!$E$14*(Inputs!$E$15*Inputs!$E$17/Inputs!$E$16+(1-Inputs!$E$15))*$C10+Inputs!$E$23*Inputs!$E$24)*(1+Inputs!$E$26)+Inputs!$E$5*(Inputs!$E$27+Inputs!$E$29) -> 6583.6999 | F10: =D10-$D$3 -> -217.48726 | G10: =E10-$D$3 -> 543.71816 | H10: =ABS(E10-D10) -> 761.20542 | I10: =H10/$D$3 -> 0.12602777
A11: =Inputs!B24 -> Type 31 maintenance scaling factor vs Type 23 | B11: =Inputs!$D$24 -> 0.6 | C11: =Inputs!$F$24 -> 1.2 | D11: =Inputs!$E$9*(1+Inputs!$E$10)+Inputs!$E$5*Inputs!$E$8*(Inputs!$E$11*Inputs!$E$14*(Inputs!$E$15*Inputs!$E$17/Inputs!$E$16+(1-Inputs!$E$15))*Inputs!$E$18+Inputs!$E$23*$B11)*(1+Inputs!$E$26)+Inputs!$E$5*(Inputs!$E$27+Inputs!$E$29) -> 5751.2045 | E11: =Inputs!$E$9*(1+Inputs!$E$10)+Inputs!$E$5*Inputs!$E$8*(Inputs!$E$11*Inputs!$E$14*(Inputs!$E$15*Inputs!$E$17/Inputs!$E$16+(1-Inputs!$E$15))*Inputs!$E$18+Inputs!$E$23*$C11)*(1+Inputs!$E$26)+Inputs!$E$5*(Inputs!$E$27+Inputs!$E$29) -> 6617.5363 | F11: =D11-$D$3 -> -288.77727 | G11: =E11-$D$3 -> 577.55455 | H11: =ABS(E11-D11) -> 866.33182 | I11: =H11/$D$3 -> 0.14343285
A12: =Inputs!B26 -> Indirect & sustaining support uplift on direct running costs | B12: =Inputs!$D$26 -> 0.3 | C12: =Inputs!$F$26 -> 0.82 | D12: =Inputs!$E$9*(1+Inputs!$E$10)+Inputs!$E$5*Inputs!$E$8*(Inputs!$E$11*Inputs!$E$14*(Inputs!$E$15*Inputs!$E$17/Inputs!$E$16+(1-Inputs!$E$15))*Inputs!$E$18+Inputs!$E$23*Inputs!$E$24)*(1+$B12)+Inputs!$E$5*(Inputs!$E$27+Inputs!$E$29) -> 5382.2076 | E12: =Inputs!$E$9*(1+Inputs!$E$10)+Inputs!$E$5*Inputs!$E$8*(Inputs!$E$11*Inputs!$E$14*(Inputs!$E$15*Inputs!$E$17/Inputs!$E$16+(1-Inputs!$E$15))*Inputs!$E$18+Inputs!$E$23*Inputs!$E$24)*(1+$C12)+Inputs!$E$5*(Inputs!$E$27+Inputs!$E$29) -> 6451.0906 | F12: =D12-$D$3 -> -657.77417 | G12: =E12-$D$3 -> 411.10886 | H12: =ABS(E12-D12) -> 1068.883 | I12: =H12/$D$3 -> 0.17696792
A13: =Inputs!B8 -> Service life per ship | B13: =Inputs!$D$8 -> 20 | C13: =Inputs!$F$8 -> 30 | D13: =Inputs!$E$9*(1+Inputs!$E$10)+Inputs!$E$5*$B13*(Inputs!$E$11*Inputs!$E$14*(Inputs!$E$15*Inputs!$E$17/Inputs!$E$16+(1-Inputs!$E$15))*Inputs!$E$18+Inputs!$E$23*Inputs!$E$24)*(1+Inputs!$E$26)+Inputs!$E$5*(Inputs!$E$27+Inputs!$E$29) -> 5373.9854 | E13: =Inputs!$E$9*(1+Inputs!$E$10)+Inputs!$E$5*$C13*(Inputs!$E$11*Inputs!$E$14*(Inputs!$E$15*Inputs!$E$17/Inputs!$E$16+(1-Inputs!$E$15))*Inputs!$E$18+Inputs!$E$23*Inputs!$E$24)*(1+Inputs!$E$26)+Inputs!$E$5*(Inputs!$E$27+Inputs!$E$29) -> 6705.9781 | F13: =D13-$D$3 -> -665.99635 | G13: =E13-$D$3 -> 665.99635 | H13: =ABS(E13-D13) -> 1331.9927 | I13: =H13/$D$3 -> 0.22052926
A15: Rows are ordered by swing, smallest first, so the largest driver appears at the top of the tornado chart. If you change Low/High values substantially, re-order rows by column H.

Sheet Risk_Results
A1: Risk analysis – Monte Carlo results
A2: 2,000 iterations · Undiscounted whole-life cost, £m approx. 2023-24 prices · Results change slightly each recalculation (F9).
B4: Statistic | C4: £m
B5: Deterministic (base case) estimate | C5: =WLC_Model!C22 -> 6039.9817
B6: Mean | C6: =AVERAGE(MC_Iterations!$T$5:$T$2004) -> 6331.7941
B7: P10 (10% chance of being lower) | C7: =PERCENTILE(MC_Iterations!$T$5:$T$2004,0.1) -> 5735.0201
B8: P50 (median) | C8: =PERCENTILE(MC_Iterations!$T$5:$T$2004,0.5) -> 6297.3155
B9: P80 (common budgeting confidence level) | C9: =PERCENTILE(MC_Iterations!$T$5:$T$2004,0.8) -> 6737.487
B10: P90 | C10: =PERCENTILE(MC_Iterations!$T$5:$T$2004,0.9) -> 6983.7825
B11: Minimum simulated | C11: =MIN(MC_Iterations!$T$5:$T$2004) -> 5002.7657
B12: Maximum simulated | C12: =MAX(MC_Iterations!$T$5:$T$2004) -> 8153.072
B13: Standard deviation | C13: =STDEV(MC_Iterations!$T$5:$T$2004) -> 474.36891
B14: Probability WLC exceeds deterministic estimate | C14: =COUNTIF(MC_Iterations!$T$5:$T$2004,">"&C5)/2000 -> 0.724
B15: Contingency needed for P80 confidence (P80 − deterministic) | C15: =C9-C5 -> 697.5053
B16: Contingency as % of deterministic estimate | C16: =C15/C5 -> 0.11548136
B19: Histogram and S-curve | F19: Bin width (£m): | G19: =(C12-C11)/25 -> 126.01225
B20: Bin upper bound (£m) | C20: Count | D20: Frequency | E20: Cumulative %
B21: =$C$11+1*$G$19 -> 5128.7779 | C21: =COUNTIFS(MC_Iterations!$T$5:$T$2004,"<="&B21) -> 2 | D21: =C21/2000 -> 0.001 | E21: =SUM($C$21:C21)/2000 -> 0.001
B22: =$C$11+2*$G$19 -> 5254.7902 | C22: =COUNTIFS(MC_Iterations!$T$5:$T$2004,">"&B21,MC_Iterations!$T$5:$T$2004,"<="&B22) -> 9 | D22: =C22/2000 -> 0.0045 | E22: =SUM($C$21:C22)/2000 -> 0.0055
B23: =$C$11+3*$G$19 -> 5380.8024 | C23: =COUNTIFS(MC_Iterations!$T$5:$T$2004,">"&B22,MC_Iterations!$T$5:$T$2004,"<="&B23) -> 14 | D23: =C23/2000 -> 0.007 | E23: =SUM($C$21:C23)/2000 -> 0.0125
B24: =$C$11+4*$G$19 -> 5506.8147 | C24: =COUNTIFS(MC_Iterations!$T$5:$T$2004,">"&B23,MC_Iterations!$T$5:$T$2004,"<="&B24) -> 33 | D24: =C24/2000 -> 0.0165 | E24: =SUM($C$21:C24)/2000 -> 0.029
B25: =$C$11+5*$G$19 -> 5632.8269 | C25: =COUNTIFS(MC_Iterations!$T$5:$T$2004,">"&B24,MC_Iterations!$T$5:$T$2004,"<="&B25) -> 63 | D25: =C25/2000 -> 0.0315 | E25: =SUM($C$21:C25)/2000 -> 0.0605
B26: =$C$11+6*$G$19 -> 5758.8392 | C26: =COUNTIFS(MC_Iterations!$T$5:$T$2004,">"&B25,MC_Iterations!$T$5:$T$2004,"<="&B26) -> 101 | D26: =C26/2000 -> 0.0505 | E26: =SUM($C$21:C26)/2000 -> 0.111
B27: =$C$11+7*$G$19 -> 5884.8514 | C27: =COUNTIFS(MC_Iterations!$T$5:$T$2004,">"&B26,MC_Iterations!$T$5:$T$2004,"<="&B27) -> 129 | D27: =C27/2000 -> 0.0645 | E27: =SUM($C$21:C27)/2000 -> 0.1755
B28: =$C$11+8*$G$19 -> 6010.8637 | C28: =COUNTIFS(MC_Iterations!$T$5:$T$2004,">"&B27,MC_Iterations!$T$5:$T$2004,"<="&B28) -> 166 | D28: =C28/2000 -> 0.083 | E28: =SUM($C$21:C28)/2000 -> 0.2585
B29: =$C$11+9*$G$19 -> 6136.8759 | C29: =COUNTIFS(MC_Iterations!$T$5:$T$2004,">"&B28,MC_Iterations!$T$5:$T$2004,"<="&B29) -> 190 | D29: =C29/2000 -> 0.095 | E29: =SUM($C$21:C29)/2000 -> 0.3535
B30: =$C$11+10*$G$19 -> 6262.8882 | C30: =COUNTIFS(MC_Iterations!$T$5:$T$2004,">"&B29,MC_Iterations!$T$5:$T$2004,"<="&B30) -> 240 | D30: =C30/2000 -> 0.12 | E30: =SUM($C$21:C30)/2000 -> 0.4735
B31: =$C$11+11*$G$19 -> 6388.9004 | C31: =COUNTIFS(MC_Iterations!$T$5:$T$2004,">"&B30,MC_Iterations!$T$5:$T$2004,"<="&B31) -> 201 | D31: =C31/2000 -> 0.1005 | E31: =SUM($C$21:C31)/2000 -> 0.574
B32: =$C$11+12*$G$19 -> 6514.9127 | C32: =COUNTIFS(MC_Iterations!$T$5:$T$2004,">"&B31,MC_Iterations!$T$5:$T$2004,"<="&B32) -> 191 | D32: =C32/2000 -> 0.0955 | E32: =SUM($C$21:C32)/2000 -> 0.6695
B33: =$C$11+13*$G$19 -> 6640.9249 | C33: =COUNTIFS(MC_Iterations!$T$5:$T$2004,">"&B32,MC_Iterations!$T$5:$T$2004,"<="&B33) -> 177 | D33: =C33/2000 -> 0.0885 | E33: =SUM($C$21:C33)/2000 -> 0.758
B34: =$C$11+14*$G$19 -> 6766.9372 | C34: =COUNTIFS(MC_Iterations!$T$5:$T$2004,">"&B33,MC_Iterations!$T$5:$T$2004,"<="&B34) -> 109 | D34: =C34/2000 -> 0.0545 | E34: =SUM($C$21:C34)/2000 -> 0.8125
B35: =$C$11+15*$G$19 -> 6892.9494 | C35: =COUNTIFS(MC_Iterations!$T$5:$T$2004,">"&B34,MC_Iterations!$T$5:$T$2004,"<="&B35) -> 107 | D35: =C35/2000 -> 0.0535 | E35: =SUM($C$21:C35)/2000 -> 0.866
B36: =$C$11+16*$G$19 -> 7018.9617 | C36: =COUNTIFS(MC_Iterations!$T$5:$T$2004,">"&B35,MC_Iterations!$T$5:$T$2004,"<="&B36) -> 89 | D36: =C36/2000 -> 0.0445 | E36: =SUM($C$21:C36)/2000 -> 0.9105
B37: =$C$11+17*$G$19 -> 7144.9739 | C37: =COUNTIFS(MC_Iterations!$T$5:$T$2004,">"&B36,MC_Iterations!$T$5:$T$2004,"<="&B37) -> 69 | D37: =C37/2000 -> 0.0345 | E37: =SUM($C$21:C37)/2000 -> 0.945
B38: =$C$11+18*$G$19 -> 7270.9862 | C38: =COUNTIFS(MC_Iterations!$T$5:$T$2004,">"&B37,MC_Iterations!$T$5:$T$2004,"<="&B38) -> 57 | D38: =C38/2000 -> 0.0285 | E38: =SUM($C$21:C38)/2000 -> 0.9735
B39: =$C$11+19*$G$19 -> 7396.9984 | C39: =COUNTIFS(MC_Iterations!$T$5:$T$2004,">"&B38,MC_Iterations!$T$5:$T$2004,"<="&B39) -> 23 | D39: =C39/2000 -> 0.0115 | E39: =SUM($C$21:C39)/2000 -> 0.985
B40: =$C$11+20*$G$19 -> 7523.0107 | C40: =COUNTIFS(MC_Iterations!$T$5:$T$2004,">"&B39,MC_Iterations!$T$5:$T$2004,"<="&B40) -> 16 | D40: =C40/2000 -> 0.008 | E40: =SUM($C$21:C40)/2000 -> 0.993
B41: =$C$11+21*$G$19 -> 7649.023 | C41: =COUNTIFS(MC_Iterations!$T$5:$T$2004,">"&B40,MC_Iterations!$T$5:$T$2004,"<="&B41) -> 3 | D41: =C41/2000 -> 0.0015 | E41: =SUM($C$21:C41)/2000 -> 0.9945
B42: =$C$11+22*$G$19 -> 7775.0352 | C42: =COUNTIFS(MC_Iterations!$T$5:$T$2004,">"&B41,MC_Iterations!$T$5:$T$2004,"<="&B42) -> 4 | D42: =C42/2000 -> 0.002 | E42: =SUM($C$21:C42)/2000 -> 0.9965
B43: =$C$11+23*$G$19 -> 7901.0475 | C43: =COUNTIFS(MC_Iterations!$T$5:$T$2004,">"&B42,MC_Iterations!$T$5:$T$2004,"<="&B43) -> 5 | D43: =C43/2000 -> 0.0025 | E43: =SUM($C$21:C43)/2000 -> 0.999
...

Sheet WLC_Model
A1: Whole-life cost model – annual profile (£m, approx. 2023-24 prices)
A2: Every cell is a formula driven by the Inputs sheet, except the acquisition spend profile (blue), which is an analyst assumption.
A4: Line | B4: ISD | C4: Total | D4: 2019 | E4: 2020 | F4: 2021 | G4: 2022 | H4: 2023 | I4: 2024 | J4: 2025 | K4: 2026 | L4: 2027 | M4: 2028 | N4: 2029 | O4: 2030 | P4: 2031 | Q4: 2032 | R4: 2033 | S4: 2034 | T4: 2035 | U4: 2036 | V4: 2037 | W4: 2038 | X4: 2039 | Y4: 2040 | Z4: 2041 | AA4: 2042 | AB4: 2043 | AC4: 2044 | AD4: 2045 | AE4: 2046 | AF4: 2047 | AG4: 2048 | AH4: 2049 | AI4: 2050 | AJ4: 2051 | AK4: 2052 | AL4: 2053 | AM4: 2054 | AN4: 2055 | AO4: 2056 | AP4: 2057 | AQ4: 2058 | AR4: 2059 | AS4: 2060 | AT4: 2061 | AU4: 2062 | AV4: 2063 | AW4: 2064 | AX4: 2065
A5: Acquisition spend profile (% of total) | C5: =SUM(D5:AX5) -> 1 | D5: 0.02 | E5: 0.04 | F5: 0.08 | G5: 0.1 | H5: 0.12 | I5: 0.13 | J5: 0.13 | K5: 0.12 | L5: 0.09 | M5: 0.07 | N5: 0.05 | O5: 0.03 | P5: 0.02 | Q5: 0 | R5: 0 | S5: 0 | T5: 0 | U5: 0 | V5: 0 | W5: 0 | X5: 0 | Y5: 0 | Z5: 0 | AA5: 0 | AB5: 0 | AC5: 0 | AD5: 0 | AE5: 0 | AF5: 0 | AG5: 0 | AH5: 0 | AI5: 0 | AJ5: 0 | AK5: 0 | AL5: 0 | AM5: 0 | AN5: 0 | AO5: 0 | AP5: 0 | AQ5: 0 | AR5: 0 | AS5: 0 | AT5: 0 | AU5: 0 | AV5: 0 | AW5: 0 | AX5: 0
A7: Ships in service
A8: Ship 1 in service (1 = yes) | B8: =Inputs!$E$6+0*Inputs!$E$7 -> 2027 | C8: =SUM(D8:AX8) -> 25 | D8: =IF(AND(D$4>=$B8,D$4<$B8+Inputs!$E$8,1<=Inputs!$E$5),1,0) -> 0 | E8: =IF(AND(E$4>=$B8,E$4<$B8+Inputs!$E$8,1<=Inputs!$E$5),1,0) -> 0 | F8: =IF(AND(F$4>=$B8,F$4<$B8+Inputs!$E$8,1<=Inputs!$E$5),1,0) -> 0 | G8: =IF(AND(G$4>=$B8,G$4<$B8+Inputs!$E$8,1<=Inputs!$E$5),1,0) -> 0 | H8: =IF(AND(H$4>=$B8,H$4<$B8+Inputs!$E$8,1<=Inputs!$E$5),1,0) -> 0 | I8: =IF(AND(I$4>=$B8,I$4<$B8+Inputs!$E$8,1<=Inputs!$E$5),1,0) -> 0 | J8: =IF(AND(J$4>=$B8,J$4<$B8+Inputs!$E$8,1<=Inputs!$E$5),1,0) -> 0 | K8: =IF(AND(K$4>=$B8,K$4<$B8+Inputs!$E$8,1<=Inputs!$E$5),1,0) -> 0 | ... AX8: =IF(AND(AX$4>=$B8,AX$4<$B8+Inputs!$E$8,1<=Inputs!$E$5),1,0) -> 0
A9: Ship 2 in service (1 = yes) | B9: =Inputs!$E$6+1*Inputs!$E$7 -> 2028 | C9: =SUM(D9:AX9) -> 25 | D9: =IF(AND(D$4>=$B9,D$4<$B9+Inputs!$E$8,2<=Inputs!$E$5),1,0) -> 0 | E9: =IF(AND(E$4>=$B9,E$4<$B9+Inputs!$E$8,2<=Inputs!$E$5),1,0) -> 0 | F9: =IF(AND(F$4>=$B9,F$4<$B9+Inputs!$E$8,2<=Inputs!$E$5),1,0) -> 0 | G9: =IF(AND(G$4>=$B9,G$4<$B9+Inputs!$E$8,2<=Inputs!$E$5),1,0) -> 0 | H9: =IF(AND(H$4>=$B9,H$4<$B9+Inputs!$E$8,2<=Inputs!$E$5),1,0) -> 0 | I9: =IF(AND(I$4>=$B9,I$4<$B9+Inputs!$E$8,2<=Inputs!$E$5),1,0) -> 0 | J9: =IF(AND(J$4>=$B9,J$4<$B9+Inputs!$E$8,2<=Inputs!$E$5),1,0) -> 0 | K9: =IF(AND(K$4>=$B9,K$4<$B9+Inputs!$E$8,2<=Inputs!$E$5),1,0) -> 0 | ... AX9: =IF(AND(AX$4>=$B9,AX$4<$B9+Inputs!$E$8,2<=Inputs!$E$5),1,0) -> 0
A10: Ship 3 in service (1 = yes) | B10: =Inputs!$E$6+2*Inputs!$E$7 -> 2029 | C10: =SUM(D10:AX10) -> 25 | D10: =IF(AND(D$4>=$B10,D$4<$B10+Inputs!$E$8,3<=Inputs!$E$5),1,0) -> 0 | E10: =IF(AND(E$4>=$B10,E$4<$B10+Inputs!$E$8,3<=Inputs!$E$5),1,0) -> 0 | F10: =IF(AND(F$4>=$B10,F$4<$B10+Inputs!$E$8,3<=Inputs!$E$5),1,0) -> 0 | G10: =IF(AND(G$4>=$B10,G$4<$B10+Inputs!$E$8,3<=Inputs!$E$5),1,0) -> 0 | H10: =IF(AND(H$4>=$B10,H$4<$B10+Inputs!$E$8,3<=Inputs!$E$5),1,0) -> 0 | I10: =IF(AND(I$4>=$B10,I$4<$B10+Inputs!$E$8,3<=Inputs!$E$5),1,0) -> 0 | J10: =IF(AND(J$4>=$B10,J$4<$B10+Inputs!$E$8,3<=Inputs!$E$5),1,0) -> 0 | K10: =IF(AND(K$4>=$B10,K$4<$B10+Inputs!$E$8,3<=Inputs!$E$5),1,0) -> 0 | ... AX10: =IF(AND(AX$4>=$B10,AX$4<$B10+Inputs!$E$8,3<=Inputs!$E$5),1,0) -> 0
A11: Ship 4 in service (1 = yes) | B11: =Inputs!$E$6+3*Inputs!$E$7 -> 2030 | C11: =SUM(D11:AX11) -> 25 | D11: =IF(AND(D$4>=$B11,D$4<$B11+Inputs!$E$8,4<=Inputs!$E$5),1,0) -> 0 | E11: =IF(AND(E$4>=$B11,E$4<$B11+Inputs!$E$8,4<=Inputs!$E$5),1,0) -> 0 | F11: =IF(AND(F$4>=$B11,F$4<$B11+Inputs!$E$8,4<=Inputs!$E$5),1,0) -> 0 | G11: =IF(AND(G$4>=$B11,G$4<$B11+Inputs!$E$8,4<=Inputs!$E$5),1,0) -> 0 | H11: =IF(AND(H$4>=$B11,H$4<$B11+Inputs!$E$8,4<=Inputs!$E$5),1,0) -> 0 | I11: =IF(AND(I$4>=$B11,I$4<$B11+Inputs!$E$8,4<=Inputs!$E$5),1,0) -> 0 | J11: =IF(AND(J$4>=$B11,J$4<$B11+Inputs!$E$8,4<=Inputs!$E$5),1,0) -> 0 | K11: =IF(AND(K$4>=$B11,K$4<$B11+Inputs!$E$8,4<=Inputs!$E$5),1,0) -> 0 | ... AX11: =IF(AND(AX$4>=$B11,AX$4<$B11+Inputs!$E$8,4<=Inputs!$E$5),1,0) -> 0
A12: Ship 5 in service (1 = yes) | B12: =Inputs!$E$6+4*Inputs!$E$7 -> 2031 | C12: =SUM(D12:AX12) -> 25 | D12: =IF(AND(D$4>=$B12,D$4<$B12+Inputs!$E$8,5<=Inputs!$E$5),1,0) -> 0 | E12: =IF(AND(E$4>=$B12,E$4<$B12+Inputs!$E$8,5<=Inputs!$E$5),1,0) -> 0 | F12: =IF(AND(F$4>=$B12,F$4<$B12+Inputs!$E$8,5<=Inputs!$E$5),1,0) -> 0 | G12: =IF(AND(G$4>=$B12,G$4<$B12+Inputs!$E$8,5<=Inputs!$E$5),1,0) -> 0 | H12: =IF(AND(H$4>=$B12,H$4<$B12+Inputs!$E$8,5<=Inputs!$E$5),1,0) -> 0 | I12: =IF(AND(I$4>=$B12,I$4<$B12+Inputs!$E$8,5<=Inputs!$E$5),1,0) -> 0 | J12: =IF(AND(J$4>=$B12,J$4<$B12+Inputs!$E$8,5<=Inputs!$E$5),1,0) -> 0 | K12: =IF(AND(K$4>=$B12,K$4<$B12+Inputs!$E$8,5<=Inputs!$E$5),1,0) -> 0 | ... AX12: =IF(AND(AX$4>=$B12,AX$4<$B12+Inputs!$E$8,5<=Inputs!$E$5),1,0) -> 0
A13: Total ships in service | C13: =SUM(D13:AX13) -> 125 | D13: =SUM(D8:D12) -> 0 | E13: =SUM(E8:E12) -> 0 | F13: =SUM(F8:F12) -> 0 | G13: =SUM(G8:G12) -> 0 | H13: =SUM(H8:H12) -> 0 | I13: =SUM(I8:I12) -> 0 | J13: =SUM(J8:J12) -> 0 | K13: =SUM(K8:K12) -> 0 | ... AX13: =SUM(AX8:AX12) -> 0
A15: Costs (£m)
A16: Acquisition | C16: =SUM(D16:AX16) -> 2310 | D16: =Inputs!$E$9*(1+Inputs!$E$10)*D$5 -> 46.2 | E16: =Inputs!$E$9*(1+Inputs!$E$10)*E$5 -> 92.4 | F16: =Inputs!$E$9*(1+Inputs!$E$10)*F$5 -> 184.8 | G16: =Inputs!$E$9*(1+Inputs!$E$10)*G$5 -> 231 | H16: =Inputs!$E$9*(1+Inputs!$E$10)*H$5 -> 277.2 | I16: =Inputs!$E$9*(1+Inputs!$E$10)*I$5 -> 300.3 | J16: =Inputs!$E$9*(1+Inputs!$E$10)*J$5 -> 300.3 | K16: =Inputs!$E$9*(1+Inputs!$E$10)*K$5 -> 277.2 | ... AX16: =Inputs!$E$9*(1+Inputs!$E$10)*AX$5 -> 0
A17: Operating (crew, fuel, port) | C17: =SUM(D17:AX17) -> 1342.514 | D17: =D$13*Inputs!$E$19 -> 0 | E17: =E$13*Inputs!$E$19 -> 0 | F17: =F$13*Inputs!$E$19 -> 0 | G17: =G$13*Inputs!$E$19 -> 0 | H17: =H$13*Inputs!$E$19 -> 0 | I17: =I$13*Inputs!$E$19 -> 0 | J17: =J$13*Inputs!$E$19 -> 0 | K17: =K$13*Inputs!$E$19 -> 0 | ... AX17: =AX$13*Inputs!$E$19 -> 0
A18: Maintenance / upkeep | C18: =SUM(D18:AX18) -> 713.0303 | D18: =D$13*Inputs!$E$25 -> 0 | E18: =E$13*Inputs!$E$25 -> 0 | F18: =F$13*Inputs!$E$25 -> 0 | G18: =G$13*Inputs!$E$25 -> 0 | H18: =H$13*Inputs!$E$25 -> 0 | I18: =I$13*Inputs!$E$25 -> 0 | J18: =J$13*Inputs!$E$25 -> 0 | K18: =K$13*Inputs!$E$25 -> 0 | ... AX18: =AX$13*Inputs!$E$25 -> 0
A19: Indirect & sustaining support | C19: =SUM(D19:AX19) -> 1274.4375 | D19: =(D17+D18)*Inputs!$E$26 -> 0 | E19: =(E17+E18)*Inputs!$E$26 -> 0 | F19: =(F17+F18)*Inputs!$E$26 -> 0 | G19: =(G17+G18)*Inputs!$E$26 -> 0 | H19: =(H17+H18)*Inputs!$E$26 -> 0 | I19: =(I17+I18)*Inputs!$E$26 -> 0 | J19: =(J17+J18)*Inputs!$E$26 -> 0 | K19: =(K17+K18)*Inputs!$E$26 -> 0 | ... AX19: =(AX17+AX18)*Inputs!$E$26 -> 0
A20: Mid-life updates | C20: =SUM(D20:AX20) -> 375 | D20: =Inputs!$E$27*SUMPRODUCT(--($B$8:$B$12+Inputs!$E$28-1=D$4),--(ROW($B$8:$B$12)-ROW($B$8)+1<=Inputs!$E$5)) -> 0 | E20: =Inputs!$E$27*SUMPRODUCT(--($B$8:$B$12+Inputs!$E$28-1=E$4),--(ROW($B$8:$B$12)-ROW($B$8)+1<=Inputs!$E$5)) -> 0 | F20: =Inputs!$E$27*SUMPRODUCT(--($B$8:$B$12+Inputs!$E$28-1=F$4),--(ROW($B$8:$B$12)-ROW($B$8)+1<=Inputs!$E$5)) -> 0 | G20: =Inputs!$E$27*SUMPRODUCT(--($B$8:$B$12+Inputs!$E$28-1=G$4),--(ROW($B$8:$B$12)-ROW($B$8)+1<=Inputs!$E$5)) -> 0 | H20: =Inputs!$E$27*SUMPRODUCT(--($B$8:$B$12+Inputs!$E$28-1=H$4),--(ROW($B$8:$B$12)-ROW($B$8)+1<=Inputs!$E$5)) -> 0 | I20: =Inputs!$E$27*SUMPRODUCT(--($B$8:$B$12+Inputs!$E$28-1=I$4),--(ROW($B$8:$B$12)-ROW($B$8)+1<=Inputs!$E$5)) -> 0 | J20: =Inputs!$E$27*SUMPRODUCT(--($B$8:$B$12+Inputs!$E$28-1=J$4),--(ROW($B$8:$B$12)-ROW($B$8)+1<=Inputs!$E$5)) -> 0 | K20: =Inputs!$E$27*SUMPRODUCT(--($B$8:$B$12+Inputs!$E$28-1=K$4),--(ROW($B$8:$B$12)-ROW($B$8)+1<=Inputs!$E$5)) -> 0 | ... AX20: =Inputs!$E$27*SUMPRODUCT(--($B$8:$B$12+Inputs!$E$28-1=AX$4),--(ROW($B$8:$B$12)-ROW($B$8)+1<=Inputs!$E$5)) -> 0
A21: Disposal | C21: =SUM(D21:AX21) -> 25 | D21: =Inputs!$E$29*SUMPRODUCT(--($B$8:$B$12+Inputs!$E$8=D$4),--(ROW($B$8:$B$12)-ROW($B$8)+1<=Inputs!$E$5)) -> 0 | E21: =Inputs!$E$29*SUMPRODUCT(--($B$8:$B$12+Inputs!$E$8=E$4),--(ROW($B$8:$B$12)-ROW($B$8)+1<=Inputs!$E$5)) -> 0 | F21: =Inputs!$E$29*SUMPRODUCT(--($B$8:$B$12+Inputs!$E$8=F$4),--(ROW($B$8:$B$12)-ROW($B$8)+1<=Inputs!$E$5)) -> 0 | G21: =Inputs!$E$29*SUMPRODUCT(--($B$8:$B$12+Inputs!$E$8=G$4),--(ROW($B$8:$B$12)-ROW($B$8)+1<=Inputs!$E$5)) -> 0 | H21: =Inputs!$E$29*SUMPRODUCT(--($B$8:$B$12+Inputs!$E$8=H$4),--(ROW($B$8:$B$12)-ROW($B$8)+1<=Inputs!$E$5)) -> 0 | I21: =Inputs!$E$29*SUMPRODUCT(--($B$8:$B$12+Inputs!$E$8=I$4),--(ROW($B$8:$B$12)-ROW($B$8)+1<=Inputs!$E$5)) -> 0 | J21: =Inputs!$E$29*SUMPRODUCT(--($B$8:$B$12+Inputs!$E$8=J$4),--(ROW($B$8:$B$12)-ROW($B$8)+1<=Inputs!$E$5)) -> 0 | K21: =Inputs!$E$29*SUMPRODUCT(--($B$8:$B$12+Inputs!$E$8=K$4),--(ROW($B$8:$B$12)-ROW($B$8)+1<=Inputs!$E$5)) -> 0 | ... AX21: =Inputs!$E$29*SUMPRODUCT(--($B$8:$B$12+Inputs!$E$8=AX$4),--(ROW($B$8:$B$12)-ROW($B$8)+1<=Inputs!$E$5)) -> 0
A22: Total cost | C22: =SUM(D22:AX22) -> 6039.9817 | D22: =SUM(D16:D21) -> 46.2 | E22: =SUM(E16:E21) -> 92.4 | F22: =SUM(F16:F21) -> 184.8 | G22: =SUM(G16:G21) -> 231 | H22: =SUM(H16:H21) -> 277.2 | I22: =SUM(I16:I21) -> 300.3 | J22: =SUM(J16:J21) -> 300.3 | K22: =SUM(K16:K21) -> 277.2 | ... AX22: =SUM(AX16:AX21) -> 0
A23: Cumulative cost | D23: =SUM($D22:D22) -> 46.2 | E23: =SUM($D22:E22) -> 138.6 | F23: =SUM($D22:F22) -> 323.4 | G23: =SUM($D22:G22) -> 554.4 | H23: =SUM($D22:H22) -> 831.6 | I23: =SUM($D22:I22) -> 1131.9 | J23: =SUM($D22:J22) -> 1432.2 | K23: =SUM($D22:K22) -> 1709.4 | ... AX23: =SUM($D22:AX22) -> 6039.9817
A25: Discount factor (future years only) | D25: =IF(D$4>=Inputs!$E$31,1/(1+Inputs!$E$30)^(D$4-Inputs!$E$31),0) -> 0 | E25: =IF(E$4>=Inputs!$E$31,1/(1+Inputs!$E$30)^(E$4-Inputs!$E$31),0) -> 0 | F25: =IF(F$4>=Inputs!$E$31,1/(1+Inputs!$E$30)^(F$4-Inputs!$E$31),0) -> 0 | G25: =IF(G$4>=Inputs!$E$31,1/(1+Inputs!$E$30)^(G$4-Inputs!$E$31),0) -> 0 | H25: =IF(H$4>=Inputs!$E$31,1/(1+Inputs!$E$30)^(H$4-Inputs!$E$31),0) -> 0 | I25: =IF(I$4>=Inputs!$E$31,1/(1+Inputs!$E$30)^(I$4-Inputs!$E$31),0) -> 0 | J25: =IF(J$4>=Inputs!$E$31,1/(1+Inputs!$E$30)^(J$4-Inputs!$E$31),0) -> 0 | K25: =IF(K$4>=Inputs!$E$31,1/(1+Inputs!$E$30)^(K$4-Inputs!$E$31),0) -> 1 | ... AX25: =IF(AX$4>=Inputs!$E$31,1/(1+Inputs!$E$30)^(AX$4-Inputs!$E$31),0) -> 0.2614125
A26: Present value of future cost | C26: =SUM(D26:AX26) -> 3117.9205 | D26: =D22*D25 -> 0 | E26: =E22*E25 -> 0 | F26: =F22*F25 -> 0 | G26: =G22*G25 -> 0 | H26: =H22*H25 -> 0 | I26: =I22*I25 -> 0 | J26: =J22*J25 -> 0 | K26: =K22*K25 -> 277.2 | ... AX26: =AX22*AX25 -> 0
A28: Check: closed-form WLC | C28: =Inputs!$E$9*(1+Inputs!$E$10)+Inputs!$E$5*Inputs!$E$8*(Inputs!$E$11*Inputs!$E$14*(Inputs!$E$15*Inputs!$E$17/Inputs!$E$16+(1-Inputs!$E$15))*Inputs!$E$18+Inputs!$E$23*Inputs!$E$24)*(1+Inputs!$E$26)+Inputs!$E$5*(Inputs!$E$27+Inputs!$E$29) -> 6039.9817
A29: Check: difference vs annual profile (should be 0) | C29: =ROUND(C22-C28,6) -> 0
A30: Check: acquisition profile sums to 100% | C30: =IF(ROUND(C5,6)=1,"OK","CHECK") -> OK

Sheet MC_Iterations
A1: Monte Carlo iterations (triangular distributions, inverse-CDF sampling)
A2: Each row is one simulated future. U = uniform random number RAND(); value = triangular inverse CDF using Low (min), Base (most likely) and High (max) from Inputs. Press F9 to re-sample.
A4: Iteration | B4: U L | C4: Service life per ship | D4: U G | E4: Acquisition cost growth above approved budget | F4: U PS | G4: Personnel share of direct operating cost | H4: U C31 | I4: Type 31 crew complement | J4: U OPU | K4: Operating cost estimating uncertainty factor | L4: U MF | M4: Type 31 maintenance scaling factor vs Type 23 | N4: U IND | O4: Indirect & sustaining support uplift on direct running costs | P4: U MLU | Q4: Mid-life update cost per ship | R4: U D | S4: Disposal cost per ship | T4: Whole-life cost (£m)
A5: 1 | B5: =RAND() -> 0.22976175 | C5: =ROUND(IF(B5<(Inputs!$E$8-Inputs!$D$8)/(Inputs!$F$8-Inputs!$D$8),Inputs!$D$8+SQRT(B5*(Inputs!$F$8-Inputs!$D$8)*(Inputs!$E$8-Inputs!$D$8)),Inputs!$F$8-SQRT((1-B5)*(Inputs!$F$8-Inputs!$D$8)*(Inputs!$F$8-Inputs!$E$8))),0) -> 23 | D5: =RAND() -> 0.11610251 | E5: =IF(D5<(Inputs!$E$10-Inputs!$D$10)/(Inputs!$F$10-Inputs!$D$10),Inputs!$D$10+SQRT(D5*(Inputs!$F$10-Inputs!$D$10)*(Inputs!$E$10-Inputs!$D$10)),Inputs!$F$10-SQRT((1-D5)*(Inputs!$F$10-Inputs!$D$10)*(Inputs!$F$10-Inputs!$E$10))) -> 0.034073818 | F5: =RAND() -> 0.7034367 | G5: =IF(F5<(Inputs!$E$15-Inputs!$D$15)/(Inputs!$F$15-Inputs!$D$15),Inputs!$D$15+SQRT(F5*(Inputs!$F$15-Inputs!$D$15)*(Inputs!$E$15-Inputs!$D$15)),Inputs!$F$15-SQRT((1-F5)*(Inputs!$F$15-Inputs!$D$15)*(Inputs!$F$15-Inputs!$E$15))) -> 0.72298529 | H5: =RAND() -> 0.45572222 | I5: =ROUND(IF(H5<(Inputs!$E$17-Inputs!$D$17)/(Inputs!$F$17-Inputs!$D$17),Inputs!$D$17+SQRT(H5*(Inputs!$F$17-Inputs!$D$17)*(Inputs!$E$17-Inputs!$D$17)),Inputs!$F$17-SQRT((1-H5)*(Inputs!$F$17-Inputs!$D$17)*(Inputs!$F$17-Inputs!$E$17))),0) -> 106 | J5: =RAND() -> 0.1825713 | K5: =IF(J5<(Inputs!$E$18-Inputs!$D$18)/(Inputs!$F$18-Inputs!$D$18),Inputs!$D$18+SQRT(J5*(Inputs!$F$18-Inputs!$D$18)*(Inputs!$E$18-Inputs!$D$18)),Inputs!$F$18-SQRT((1-J5)*(Inputs!$F$18-Inputs!$D$18)*(Inputs!$F$18-Inputs!$E$18))) -> 0.97993745 | L5: =RAND() -> 0.61413217 | M5: =IF(L5<(Inputs!$E$24-Inputs!$D$24)/(Inputs!$F$24-Inputs!$D$24),Inputs!$D$24+SQRT(L5*(Inputs!$F$24-Inputs!$D$24)*(Inputs!$E$24-Inputs!$D$24)),Inputs!$F$24-SQRT((1-L5)*(Inputs!$F$24-Inputs!$D$24)*(Inputs!$F$24-Inputs!$E$24))) -> 0.89568391 | N5: =RAND() -> 0.28957016 | O5: =IF(N5<(Inputs!$E$26-Inputs!$D$26)/(Inputs!$F$26-Inputs!$D$26),Inputs!$D$26+SQRT(N5*(Inputs!$F$26-Inputs!$D$26)*(Inputs!$E$26-Inputs!$D$26)),Inputs!$F$26-SQRT((1-N5)*(Inputs!$F$26-Inputs!$D$26)*(Inputs!$F$26-Inputs!$E$26))) -> 0.51950962 | P5: =RAND() -> 0.4910455 | Q5: =IF(P5<(Inputs!$E$27-Inputs!$D$27)/(Inputs!$F$27-Inputs!$D$27),Inputs!$D$27+SQRT(P5*(Inputs!$F$27-Inputs!$D$27)*(Inputs!$E$27-Inputs!$D$27)),Inputs!$F$27-SQRT((1-P5)*(Inputs!$F$27-Inputs!$D$27)*(Inputs!$F$27-Inputs!$E$27))) -> 88.216841 | R5: =RAND() -> 0.56329314 | S5: =IF(R5<(Inputs!$E$29-Inputs!$D$29)/(Inputs!$F$29-Inputs!$D$29),Inputs!$D$29+SQRT(R5*(Inputs!$F$29-Inputs!$D$29)*(Inputs!$E$29-Inputs!$D$29)),Inputs!$F$29-SQRT((1-R5)*(Inputs!$F$29-Inputs!$D$29)*(Inputs!$F$29-Inputs!$E$29))) -> 7.4652876 | T5: =Inputs!$E$9*(1+E5)+Inputs!$E$5*C5*(Inputs!$E$11*Inputs!$E$14*(G5*I5/Inputs!$E$16+(1-G5))*K5+Inputs!$E$23*M5)*(1+O5)+Inputs!$E$5*(Q5+S5) -> 5692.5777
A6: 2 | B6: =RAND() -> 0.57817997 | C6: =ROUND(IF(B6<(Inputs!$E$8-Inputs!$D$8)/(Inputs!$F$8-Inputs!$D$8),Inputs!$D$8+SQRT(B6*(Inputs!$F$8-Inputs!$D$8)*(Inputs!$E$8-Inputs!$D$8)),Inputs!$F$8-SQRT((1-B6)*(Inputs!$F$8-Inputs!$D$8)*(Inputs!$F$8-Inputs!$E$8))),0) -> 25 | D6: =RAND() -> 0.41151208 | E6: =IF(D6<(Inputs!$E$10-Inputs!$D$10)/(Inputs!$F$10-Inputs!$D$10),Inputs!$D$10+SQRT(D6*(Inputs!$F$10-Inputs!$D$10)*(Inputs!$E$10-Inputs!$D$10)),Inputs!$F$10-SQRT((1-D6)*(Inputs!$F$10-Inputs!$D$10)*(Inputs!$F$10-Inputs!$E$10))) -> 0.067129245 | F6: =RAND() -> 0.52368159 | G6: =IF(F6<(Inputs!$E$15-Inputs!$D$15)/(Inputs!$F$15-Inputs!$D$15),Inputs!$D$15+SQRT(F6*(Inputs!$F$15-Inputs!$D$15)*(Inputs!$E$15-Inputs!$D$15)),Inputs!$F$15-SQRT((1-F6)*(Inputs!$F$15-Inputs!$D$15)*(Inputs!$F$15-Inputs!$E$15))) -> 0.70239688 | H6: =RAND() -> 0.6779202 | I6: =ROUND(IF(H6<(Inputs!$E$17-Inputs!$D$17)/(Inputs!$F$17-Inputs!$D$17),Inputs!$D$17+SQRT(H6*(Inputs!$F$17-Inputs!$D$17)*(Inputs!$E$17-Inputs!$D$17)),Inputs!$F$17-SQRT((1-H6)*(Inputs!$F$17-Inputs!$D$17)*(Inputs!$F$17-Inputs!$E$17))),0) -> 108 | J6: =RAND() -> 0.11855476 | K6: =IF(J6<(Inputs!$E$18-Inputs!$D$18)/(Inputs!$F$18-Inputs!$D$18),Inputs!$D$18+SQRT(J6*(Inputs!$F$18-Inputs!$D$18)*(Inputs!$E$18-Inputs!$D$18)),Inputs!$F$18-SQRT((1-J6)*(Inputs!$F$18-Inputs!$D$18)*(Inputs!$F$18-Inputs!$E$18))) -> 0.96441597 | L6: =RAND() -> 0.60640562 | M6: =IF(L6<(Inputs!$E$24-Inputs!$D$24)/(Inputs!$F$24-Inputs!$D$24),Inputs!$D$24+SQRT(L6*(Inputs!$F$24-Inputs!$D$24)*(Inputs!$E$24-Inputs!$D$24)),Inputs!$F$24-SQRT((1-L6)*(Inputs!$F$24-Inputs!$D$24)*(Inputs!$F$24-Inputs!$E$24))) -> 0.89265223 | N6: =RAND() -> 0.33660534 | O6: =IF(N6<(Inputs!$E$26-Inputs!$D$26)/(Inputs!$F$26-Inputs!$D$26),Inputs!$D$26+SQRT(N6*(Inputs!$F$26-Inputs!$D$26)*(Inputs!$E$26-Inputs!$D$26)),Inputs!$F$26-SQRT((1-N6)*(Inputs!$F$26-Inputs!$D$26)*(Inputs!$F$26-Inputs!$E$26))) -> 0.53666671 | P6: =RAND() -> 0.66975076 | Q6: =IF(P6<(Inputs!$E$27-Inputs!$D$27)/(Inputs!$F$27-Inputs!$D$27),Inputs!$D$27+SQRT(P6*(Inputs!$F$27-Inputs!$D$27)*(Inputs!$E$27-Inputs!$D$27)),Inputs!$F$27-SQRT((1-P6)*(Inputs!$F$27-Inputs!$D$27)*(Inputs!$F$27-Inputs!$E$27))) -> 100.23184 | R6: =RAND() -> 0.96138344 | S6: =IF(R6<(Inputs!$E$29-Inputs!$D$29)/(Inputs!$F$29-Inputs!$D$29),Inputs!$D$29+SQRT(R6*(Inputs!$F$29-Inputs!$D$29)*(Inputs!$E$29-Inputs!$D$29)),Inputs!$F$29-SQRT((1-R6)*(Inputs!$F$29-Inputs!$D$29)*(Inputs!$F$29-Inputs!$E$29))) -> 12.75943 | T6: =Inputs!$E$9*(1+E6)+Inputs!$E$5*C6*(Inputs!$E$11*Inputs!$E$14*(G6*I6/Inputs!$E$16+(1-G6))*K6+Inputs!$E$23*M6)*(1+O6)+Inputs!$E$5*(Q6+S6) -> 6154.3572
A7: 3 | B7: =RAND() -> 0.77289138 | C7: =ROUND(IF(B7<(Inputs!$E$8-Inputs!$D$8)/(Inputs!$F$8-Inputs!$D$8),Inputs!$D$8+SQRT(B7*(Inputs!$F$8-Inputs!$D$8)*(Inputs!$E$8-Inputs!$D$8)),Inputs!$F$8-SQRT((1-B7)*(Inputs!$F$8-Inputs!$D$8)*(Inputs!$F$8-Inputs!$E$8))),0) -> 27 | D7: =RAND() -> 0.29295079 | E7: =IF(D7<(Inputs!$E$10-Inputs!$D$10)/(Inputs!$F$10-Inputs!$D$10),Inputs!$D$10+SQRT(D7*(Inputs!$F$10-Inputs!$D$10)*(Inputs!$E$10-Inputs!$D$10)),Inputs!$F$10-SQRT((1-D7)*(Inputs!$F$10-Inputs!$D$10)*(Inputs!$F$10-Inputs!$E$10))) -> 0.054358398 | F7: =RAND() -> 0.91857875 | G7: =IF(F7<(Inputs!$E$15-Inputs!$D$15)/(Inputs!$F$15-Inputs!$D$15),Inputs!$D$15+SQRT(F7*(Inputs!$F$15-Inputs!$D$15)*(Inputs!$E$15-Inputs!$D$15)),Inputs!$F$15-SQRT((1-F7)*(Inputs!$F$15-Inputs!$D$15)*(Inputs!$F$15-Inputs!$E$15))) -> 0.75964625 | H7: =RAND() -> 0.27059352 | I7: =ROUND(IF(H7<(Inputs!$E$17-Inputs!$D$17)/(Inputs!$F$17-Inputs!$D$17),Inputs!$D$17+SQRT(H7*(Inputs!$F$17-Inputs!$D$17)*(Inputs!$E$17-Inputs!$D$17)),Inputs!$F$17-SQRT((1-H7)*(Inputs!$F$17-Inputs!$D$17)*(Inputs!$F$17-Inputs!$E$17))),0) -> 105 | J7: =RAND() -> 0.2905444 | K7: =IF(J7<(Inputs!$E$18-Inputs!$D$18)/(Inputs!$F$18-Inputs!$D$18),Inputs!$D$18+SQRT(J7*(Inputs!$F$18-Inputs!$D$18)*(Inputs!$E$18-Inputs!$D$18)),Inputs!$F$18-SQRT((1-J7)*(Inputs!$F$18-Inputs!$D$18)*(Inputs!$F$18-Inputs!$E$18))) -> 1.0008467 | L7: =RAND() -> 0.97731378 | M7: =IF(L7<(Inputs!$E$24-Inputs!$D$24)/(Inputs!$F$24-Inputs!$D$24),Inputs!$D$24+SQRT(L7*(Inputs!$F$24-Inputs!$D$24)*(Inputs!$E$24-Inputs!$D$24)),Inputs!$F$24-SQRT((1-L7)*(Inputs!$F$24-Inputs!$D$24)*(Inputs!$F$24-Inputs!$E$24))) -> 1.1262118 | N7: =RAND() -> 0.44650671 | O7: =IF(N7<(Inputs!$E$26-Inputs!$D$26)/(Inputs!$F$26-Inputs!$D$26),Inputs!$D$26+SQRT(N7*(Inputs!$F$26-Inputs!$D$26)*(Inputs!$E$26-Inputs!$D$26)),Inputs!$F$26-SQRT((1-N7)*(Inputs!$F$26-Inputs!$D$26)*(Inputs!$F$26-Inputs!$E$26))) -> 0.57257791 | P7: =RAND() -> 0.15559261 | Q7: =IF(P7<(Inputs!$E$27-Inputs!$D$27)/(Inputs!$F$27-Inputs!$D$27),Inputs!$D$27+SQRT(P7*(Inputs!$F$27-Inputs!$D$27)*(Inputs!$E$27-Inputs!$D$27)),Inputs!$F$27-SQRT((1-P7)*(Inputs!$F$27-Inputs!$D$27)*(Inputs!$F$27-Inputs!$E$27))) -> 69.722615 | R7: =RAND() -> 0.41167665 | S7: =IF(R7<(Inputs!$E$29-Inputs!$D$29)/(Inputs!$F$29-Inputs!$D$29),Inputs!$D$29+SQRT(R7*(Inputs!$F$29-Inputs!$D$29)*(Inputs!$E$29-Inputs!$D$29)),Inputs!$F$29-SQRT((1-R7)*(Inputs!$F$29-Inputs!$D$29)*(Inputs!$F$29-Inputs!$E$29))) -> 6.2545992 | T7: =Inputs!$E$9*(1+E7)+Inputs!$E$5*C7*(Inputs!$E$11*Inputs!$E$14*(G7*I7/Inputs!$E$16+(1-G7))*K7+Inputs!$E$23*M7)*(1+O7)+Inputs!$E$5*(Q7+S7) -> 6601.8995
A8: 4 | B8: =RAND() -> 0.2049388 | C8: =ROUND(IF(B8<(Inputs!$E$8-Inputs!$D$8)/(Inputs!$F$8-Inputs!$D$8),Inputs!$D$8+SQRT(B8*(Inputs!$F$8-Inputs!$D$8)*(Inputs!$E$8-Inputs!$D$8)),Inputs!$F$8-SQRT((1-B8)*(Inputs!$F$8-Inputs!$D$8)*(Inputs!$F$8-Inputs!$E$8))),0) -> 23 | D8: =RAND() -> 0.87256793 | E8: =IF(D8<(Inputs!$E$10-Inputs!$D$10)/(Inputs!$F$10-Inputs!$D$10),Inputs!$D$10+SQRT(D8*(Inputs!$F$10-Inputs!$D$10)*(Inputs!$E$10-Inputs!$D$10)),Inputs!$F$10-SQRT((1-D8)*(Inputs!$F$10-Inputs!$D$10)*(Inputs!$F$10-Inputs!$E$10))) -> 0.13816989 | F8: =RAND() -> 0.3441313 | G8: =IF(F8<(Inputs!$E$15-Inputs!$D$15)/(Inputs!$F$15-Inputs!$D$15),Inputs!$D$15+SQRT(F8*(Inputs!$F$15-Inputs!$D$15)*(Inputs!$E$15-Inputs!$D$15)),Inputs!$F$15-SQRT((1-F8)*(Inputs!$F$15-Inputs!$D$15)*(Inputs!$F$15-Inputs!$E$15))) -> 0.68296159 | H8: =RAND() -> 0.3722731 | I8: =ROUND(IF(H8<(Inputs!$E$17-Inputs!$D$17)/(Inputs!$F$17-Inputs!$D$17),Inputs!$D$17+SQRT(H8*(Inputs!$F$17-Inputs!$D$17)*(Inputs!$E$17-Inputs!$D$17)),Inputs!$F$17-SQRT((1-H8)*(Inputs!$F$17-Inputs!$D$17)*(Inputs!$F$17-Inputs!$E$17))),0) -> 105 | J8: =RAND() -> 0.15824309 | K8: =IF(J8<(Inputs!$E$18-Inputs!$D$18)/(Inputs!$F$18-Inputs!$D$18),Inputs!$D$18+SQRT(J8*(Inputs!$F$18-Inputs!$D$18)*(Inputs!$E$18-Inputs!$D$18)),Inputs!$F$18-SQRT((1-J8)*(Inputs!$F$18-Inputs!$D$18)*(Inputs!$F$18-Inputs!$E$18))) -> 0.97442115 | L8: =RAND() -> 0.9141667 | M8: =IF(L8<(Inputs!$E$24-Inputs!$D$24)/(Inputs!$F$24-Inputs!$D$24),Inputs!$D$24+SQRT(L8*(Inputs!$F$24-Inputs!$D$24)*(Inputs!$E$24-Inputs!$D$24)),Inputs!$F$24-SQRT((1-L8)*(Inputs!$F$24-Inputs!$D$24)*(Inputs!$F$24-Inputs!$E$24))) -> 1.056473 | N8: =RAND() -> 0.72703941 | O8: =IF(N8<(Inputs!$E$26-Inputs!$D$26)/(Inputs!$F$26-Inputs!$D$26),Inputs!$D$26+SQRT(N8*(Inputs!$F$26-Inputs!$D$26)*(Inputs!$E$26-Inputs!$D$26)),Inputs!$F$26-SQRT((1-N8)*(Inputs!$F$26-Inputs!$D$26)*(Inputs!$F$26-Inputs!$E$26))) -> 0.6515129 | P8: =RAND() -> 0.14015444 | Q8: =IF(P8<(Inputs!$E$27-Inputs!$D$27)/(Inputs!$F$27-Inputs!$D$27),Inputs!$D$27+SQRT(P8*(Inputs!$F$27-Inputs!$D$27)*(Inputs!$E$27-Inputs!$D$27)),Inputs!$F$27-SQRT((1-P8)*(Inputs!$F$27-Inputs!$D$27)*(Inputs!$F$27-Inputs!$E$27))) -> 68.718603 | R8: =RAND() -> 0.69128483 | S8: =IF(R8<(Inputs!$E$29-Inputs!$D$29)/(Inputs!$F$29-Inputs!$D$29),Inputs!$D$29+SQRT(R8*(Inputs!$F$29-Inputs!$D$29)*(Inputs!$E$29-Inputs!$D$29)),Inputs!$F$29-SQRT((1-R8)*(Inputs!$F$29-Inputs!$D$29)*(Inputs!$F$29-Inputs!$E$29))) -> 8.664941 | T8: =Inputs!$E$9*(1+E8)+Inputs!$E$5*C8*(Inputs!$E$11*Inputs!$E$14*(G8*I8/Inputs!$E$16+(1-G8))*K8+Inputs!$E$23*M8)*(1+O8)+Inputs!$E$5*(Q8+S8) -> 6330.2149
